[2024-10-30T23:21:00.194+0000] {local_task_job_runner.py:120} INFO - ::group::Pre task execution logs
[2024-10-30T23:21:01.929+0000] {taskinstance.py:2076} INFO - Dependencies all met for dep_context=non-requeueable deps ti=<TaskInstance: sensor_data.sensor_data_generator scheduled__2024-10-30T23:15:00+00:00 [queued]>
[2024-10-30T23:21:02.214+0000] {taskinstance.py:2076} INFO - Dependencies all met for dep_context=requeueable deps ti=<TaskInstance: sensor_data.sensor_data_generator scheduled__2024-10-30T23:15:00+00:00 [queued]>
[2024-10-30T23:21:02.223+0000] {taskinstance.py:2306} INFO - Starting attempt 1 of 1
[2024-10-30T23:21:02.611+0000] {taskinstance.py:2330} INFO - Executing <Task(PythonOperator): sensor_data_generator> on 2024-10-30 23:15:00+00:00
[2024-10-30T23:21:02.802+0000] {standard_task_runner.py:64} INFO - Started process 2612 to run task
[2024-10-30T23:21:02.827+0000] {standard_task_runner.py:90} INFO - Running: ['***', 'tasks', 'run', 'sensor_data', 'sensor_data_generator', 'scheduled__2024-10-30T23:15:00+00:00', '--job-id', '68', '--raw', '--subdir', 'DAGS_FOLDER/sensor_***.py', '--cfg-path', '/tmp/tmpl9qixgz8']
[2024-10-30T23:21:03.019+0000] {standard_task_runner.py:91} INFO - Job 68: Subtask sensor_data_generator
[2024-10-30T23:21:04.048+0000] {task_command.py:426} INFO - Running <TaskInstance: sensor_data.sensor_data_generator scheduled__2024-10-30T23:15:00+00:00 [running]> on host 5d793f8b441e
[2024-10-30T23:21:05.693+0000] {taskinstance.py:2648} INFO - Exporting env vars: AIRFLOW_CTX_DAG_OWNER='Bich Ly' AIRFLOW_CTX_DAG_ID='sensor_data' AIRFLOW_CTX_TASK_ID='sensor_data_generator' AIRFLOW_CTX_EXECUTION_DATE='2024-10-30T23:15:00+00:00' AIRFLOW_CTX_TRY_NUMBER='1' AIRFLOW_CTX_DAG_RUN_ID='scheduled__2024-10-30T23:15:00+00:00'
[2024-10-30T23:21:05.704+0000] {taskinstance.py:430} INFO - ::endgroup::
[2024-10-30T23:21:05.944+0000] {conn.py:1527} WARNING - DNS lookup failed for broker:9092, exception was [Errno -3] Temporary failure in name resolution. Is your advertised.listeners (called advertised.host.name before Kafka 9) correct and resolvable?
[2024-10-30T23:21:05.949+0000] {conn.py:315} ERROR - DNS lookup failed for broker:9092 (0)
[2024-10-30T23:21:05.949+0000] {conn.py:1205} INFO - Probing node bootstrap-0 broker version
[2024-10-30T23:21:06.017+0000] {conn.py:1527} WARNING - DNS lookup failed for broker:9092, exception was [Errno -3] Temporary failure in name resolution. Is your advertised.listeners (called advertised.host.name before Kafka 9) correct and resolvable?
[2024-10-30T23:21:06.018+0000] {conn.py:315} ERROR - DNS lookup failed for broker:9092 (0)
[2024-10-30T23:21:06.030+0000] {conn.py:1527} WARNING - DNS lookup failed for broker:9092, exception was [Errno -3] Temporary failure in name resolution. Is your advertised.listeners (called advertised.host.name before Kafka 9) correct and resolvable?
[2024-10-30T23:21:06.031+0000] {conn.py:315} ERROR - DNS lookup failed for broker:9092 (0)
[2024-10-30T23:21:06.032+0000] {conn.py:1205} INFO - Probing node bootstrap-0 broker version
[2024-10-30T23:21:06.046+0000] {conn.py:1527} WARNING - DNS lookup failed for broker:9092, exception was [Errno -3] Temporary failure in name resolution. Is your advertised.listeners (called advertised.host.name before Kafka 9) correct and resolvable?
[2024-10-30T23:21:06.047+0000] {conn.py:315} ERROR - DNS lookup failed for broker:9092 (0)
[2024-10-30T23:21:06.047+0000] {taskinstance.py:441} INFO - ::group::Post task execution logs
[2024-10-30T23:21:06.048+0000] {taskinstance.py:2905} ERROR - Task failed with exception
Traceback (most recent call last):
  File "/home/airflow/.local/lib/python3.11/site-packages/airflow/models/taskinstance.py", line 465, in _execute_task
    result = _execute_callable(context=context, **execute_callable_kwargs)
             ^^^^^^^^^^^^^^^^^^^^^^^^^^^^^^^^^^^^^^^^^^^^^^^^^^^^^^^^^^^^^
  File "/home/airflow/.local/lib/python3.11/site-packages/airflow/models/taskinstance.py", line 432, in _execute_callable
    return execute_callable(context=context, **execute_callable_kwargs)
           ^^^^^^^^^^^^^^^^^^^^^^^^^^^^^^^^^^^^^^^^^^^^^^^^^^^^^^^^^^^^
  File "/home/airflow/.local/lib/python3.11/site-packages/airflow/models/baseoperator.py", line 401, in wrapper
    return func(self, *args, **kwargs)
           ^^^^^^^^^^^^^^^^^^^^^^^^^^^
  File "/home/airflow/.local/lib/python3.11/site-packages/airflow/operators/python.py", line 235, in execute
    return_value = self.execute_callable()
                   ^^^^^^^^^^^^^^^^^^^^^^^
  File "/home/airflow/.local/lib/python3.11/site-packages/airflow/operators/python.py", line 252, in execute_callable
    return self.python_callable(*self.op_args, **self.op_kwargs)
           ^^^^^^^^^^^^^^^^^^^^^^^^^^^^^^^^^^^^^^^^^^^^^^^^^^^^^
  File "/opt/airflow/dags/sensor_airflow.py", line 24, in stream_data
    producer = KafkaProducer(bootstrap_servers=['broker:9092'], max_block_ms=5000)
               ^^^^^^^^^^^^^^^^^^^^^^^^^^^^^^^^^^^^^^^^^^^^^^^^^^^^^^^^^^^^^^^^^^^
  File "/home/airflow/.local/lib/python3.11/site-packages/kafka/producer/kafka.py", line 381, in __init__
    client = KafkaClient(metrics=self._metrics, metric_group_prefix='producer',
             ^^^^^^^^^^^^^^^^^^^^^^^^^^^^^^^^^^^^^^^^^^^^^^^^^^^^^^^^^^^^^^^^^^
  File "/home/airflow/.local/lib/python3.11/site-packages/kafka/client_async.py", line 244, in __init__
    self.config['api_version'] = self.check_version(timeout=check_timeout)
                                 ^^^^^^^^^^^^^^^^^^^^^^^^^^^^^^^^^^^^^^^^^
  File "/home/airflow/.local/lib/python3.11/site-packages/kafka/client_async.py", line 900, in check_version
    raise Errors.NoBrokersAvailable()
kafka.errors.NoBrokersAvailable: NoBrokersAvailable
[2024-10-30T23:21:06.071+0000] {taskinstance.py:1206} INFO - Marking task as FAILED. dag_id=sensor_data, task_id=sensor_data_generator, run_id=scheduled__2024-10-30T23:15:00+00:00, execution_date=20241030T231500, start_date=20241030T232101, end_date=20241030T232106
[2024-10-30T23:21:06.343+0000] {standard_task_runner.py:110} ERROR - Failed to execute job 68 for task sensor_data_generator (NoBrokersAvailable; 2612)
[2024-10-30T23:21:06.393+0000] {local_task_job_runner.py:243} INFO - Task exited with return code 1
[2024-10-30T23:21:06.619+0000] {taskinstance.py:3503} INFO - 0 downstream tasks scheduled from follow-on schedule check
[2024-10-30T23:21:06.638+0000] {local_task_job_runner.py:222} INFO - ::endgroup::
