[2024-11-12T08:24:04.691+0000] {local_task_job_runner.py:120} INFO - ::group::Pre task execution logs
[2024-11-12T08:24:04.784+0000] {taskinstance.py:2076} INFO - Dependencies all met for dep_context=non-requeueable deps ti=<TaskInstance: fetch_data.fetch_data_from_api scheduled__2024-11-12T08:21:00+00:00 [queued]>
[2024-11-12T08:24:04.815+0000] {taskinstance.py:2076} INFO - Dependencies all met for dep_context=requeueable deps ti=<TaskInstance: fetch_data.fetch_data_from_api scheduled__2024-11-12T08:21:00+00:00 [queued]>
[2024-11-12T08:24:04.816+0000] {taskinstance.py:2306} INFO - Starting attempt 1 of 1
[2024-11-12T08:24:05.144+0000] {taskinstance.py:2330} INFO - Executing <Task(PythonOperator): fetch_data_from_api> on 2024-11-12 08:21:00+00:00
[2024-11-12T08:24:05.159+0000] {standard_task_runner.py:64} INFO - Started process 1499 to run task
[2024-11-12T08:24:05.164+0000] {standard_task_runner.py:90} INFO - Running: ['***', 'tasks', 'run', 'fetch_data', 'fetch_data_from_api', 'scheduled__2024-11-12T08:21:00+00:00', '--job-id', '510', '--raw', '--subdir', 'DAGS_FOLDER/***_producer.py', '--cfg-path', '/tmp/tmpmtg3qw_r']
[2024-11-12T08:24:05.167+0000] {standard_task_runner.py:91} INFO - Job 510: Subtask fetch_data_from_api
[2024-11-12T08:24:05.280+0000] {task_command.py:426} INFO - Running <TaskInstance: fetch_data.fetch_data_from_api scheduled__2024-11-12T08:21:00+00:00 [running]> on host 4456ca8d9d4c
[2024-11-12T08:24:05.460+0000] {taskinstance.py:2648} INFO - Exporting env vars: AIRFLOW_CTX_DAG_OWNER='Bich Ly' AIRFLOW_CTX_DAG_ID='fetch_data' AIRFLOW_CTX_TASK_ID='fetch_data_from_api' AIRFLOW_CTX_EXECUTION_DATE='2024-11-12T08:21:00+00:00' AIRFLOW_CTX_TRY_NUMBER='1' AIRFLOW_CTX_DAG_RUN_ID='scheduled__2024-11-12T08:21:00+00:00'
[2024-11-12T08:24:05.461+0000] {taskinstance.py:430} INFO - ::endgroup::
[2024-11-12T08:24:05.575+0000] {conn.py:380} INFO - <BrokerConnection node_id=bootstrap-0 host=10.0.2.15:9092 <connecting> [IPv4 ('10.0.2.15', 9092)]>: connecting to 10.0.2.15:9092 [('10.0.2.15', 9092) IPv4]
[2024-11-12T08:24:05.577+0000] {conn.py:410} INFO - <BrokerConnection node_id=bootstrap-0 host=10.0.2.15:9092 <connecting> [IPv4 ('10.0.2.15', 9092)]>: Connection complete.
[2024-11-12T08:28:29.923+0000] {job.py:218} ERROR - Job heartbeat got an exception
Traceback (most recent call last):
  File "/home/airflow/.local/lib/python3.11/site-packages/sqlalchemy/engine/base.py", line 3371, in _wrap_pool_connect
    return fn()
           ^^^^
  File "/home/airflow/.local/lib/python3.11/site-packages/sqlalchemy/pool/base.py", line 327, in connect
    return _ConnectionFairy._checkout(self)
           ^^^^^^^^^^^^^^^^^^^^^^^^^^^^^^^^
  File "/home/airflow/.local/lib/python3.11/site-packages/sqlalchemy/pool/base.py", line 894, in _checkout
    fairy = _ConnectionRecord.checkout(pool)
            ^^^^^^^^^^^^^^^^^^^^^^^^^^^^^^^^
  File "/home/airflow/.local/lib/python3.11/site-packages/sqlalchemy/pool/base.py", line 493, in checkout
    rec = pool._do_get()
          ^^^^^^^^^^^^^^
  File "/home/airflow/.local/lib/python3.11/site-packages/sqlalchemy/pool/impl.py", line 256, in _do_get
    return self._create_connection()
           ^^^^^^^^^^^^^^^^^^^^^^^^^
  File "/home/airflow/.local/lib/python3.11/site-packages/sqlalchemy/pool/base.py", line 273, in _create_connection
    return _ConnectionRecord(self)
           ^^^^^^^^^^^^^^^^^^^^^^^
  File "/home/airflow/.local/lib/python3.11/site-packages/sqlalchemy/pool/base.py", line 388, in __init__
    self.__connect()
  File "/home/airflow/.local/lib/python3.11/site-packages/sqlalchemy/pool/base.py", line 690, in __connect
    with util.safe_reraise():
  File "/home/airflow/.local/lib/python3.11/site-packages/sqlalchemy/util/langhelpers.py", line 70, in __exit__
    compat.raise_(
  File "/home/airflow/.local/lib/python3.11/site-packages/sqlalchemy/util/compat.py", line 211, in raise_
    raise exception
  File "/home/airflow/.local/lib/python3.11/site-packages/sqlalchemy/pool/base.py", line 686, in __connect
    self.dbapi_connection = connection = pool._invoke_creator(self)
                                         ^^^^^^^^^^^^^^^^^^^^^^^^^^
  File "/home/airflow/.local/lib/python3.11/site-packages/sqlalchemy/engine/create.py", line 574, in connect
    return dialect.connect(*cargs, **cparams)
           ^^^^^^^^^^^^^^^^^^^^^^^^^^^^^^^^^^
  File "/home/airflow/.local/lib/python3.11/site-packages/sqlalchemy/engine/default.py", line 598, in connect
    return self.dbapi.connect(*cargs, **cparams)
           ^^^^^^^^^^^^^^^^^^^^^^^^^^^^^^^^^^^^^
  File "/home/airflow/.local/lib/python3.11/site-packages/psycopg2/__init__.py", line 122, in connect
    conn = _connect(dsn, connection_factory=connection_factory, **kwasync)
           ^^^^^^^^^^^^^^^^^^^^^^^^^^^^^^^^^^^^^^^^^^^^^^^^^^^^^^^^^^^^^^^
psycopg2.OperationalError: could not translate host name "postgres" to address: Temporary failure in name resolution


The above exception was the direct cause of the following exception:

Traceback (most recent call last):
  File "/home/airflow/.local/lib/python3.11/site-packages/airflow/jobs/job.py", line 213, in heartbeat
    heartbeat_callback(session)
  File "/home/airflow/.local/lib/python3.11/site-packages/airflow/utils/session.py", line 76, in wrapper
    return func(*args, **kwargs)
           ^^^^^^^^^^^^^^^^^^^^^
  File "/home/airflow/.local/lib/python3.11/site-packages/airflow/jobs/local_task_job_runner.py", line 261, in heartbeat_callback
    self.task_instance.refresh_from_db()
  File "/home/airflow/.local/lib/python3.11/site-packages/airflow/utils/session.py", line 79, in wrapper
    return func(*args, session=session, **kwargs)
           ^^^^^^^^^^^^^^^^^^^^^^^^^^^^^^^^^^^^^^
  File "/home/airflow/.local/lib/python3.11/site-packages/airflow/models/taskinstance.py", line 1821, in refresh_from_db
    _refresh_from_db(task_instance=self, session=session, lock_for_update=lock_for_update)
  File "/home/airflow/.local/lib/python3.11/site-packages/airflow/models/taskinstance.py", line 510, in _refresh_from_db
    ti = TaskInstance.get_task_instance(
         ^^^^^^^^^^^^^^^^^^^^^^^^^^^^^^^
  File "/home/airflow/.local/lib/python3.11/site-packages/airflow/api_internal/internal_api_call.py", line 115, in wrapper
    return func(*args, **kwargs)
           ^^^^^^^^^^^^^^^^^^^^^
  File "/home/airflow/.local/lib/python3.11/site-packages/airflow/utils/session.py", line 76, in wrapper
    return func(*args, **kwargs)
           ^^^^^^^^^^^^^^^^^^^^^
  File "/home/airflow/.local/lib/python3.11/site-packages/airflow/models/taskinstance.py", line 1807, in get_task_instance
    return query.one_or_none()
           ^^^^^^^^^^^^^^^^^^^
  File "/home/airflow/.local/lib/python3.11/site-packages/sqlalchemy/orm/query.py", line 2850, in one_or_none
    return self._iter().one_or_none()
           ^^^^^^^^^^^^
  File "/home/airflow/.local/lib/python3.11/site-packages/sqlalchemy/orm/query.py", line 2916, in _iter
    result = self.session.execute(
             ^^^^^^^^^^^^^^^^^^^^^
  File "/home/airflow/.local/lib/python3.11/site-packages/sqlalchemy/orm/session.py", line 1716, in execute
    conn = self._connection_for_bind(bind)
           ^^^^^^^^^^^^^^^^^^^^^^^^^^^^^^^
  File "/home/airflow/.local/lib/python3.11/site-packages/sqlalchemy/orm/session.py", line 1555, in _connection_for_bind
    return self._transaction._connection_for_bind(
           ^^^^^^^^^^^^^^^^^^^^^^^^^^^^^^^^^^^^^^^
  File "/home/airflow/.local/lib/python3.11/site-packages/sqlalchemy/orm/session.py", line 750, in _connection_for_bind
    conn = bind.connect()
           ^^^^^^^^^^^^^^
  File "/home/airflow/.local/lib/python3.11/site-packages/sqlalchemy/future/engine.py", line 412, in connect
    return super(Engine, self).connect()
           ^^^^^^^^^^^^^^^^^^^^^^^^^^^^^
  File "/home/airflow/.local/lib/python3.11/site-packages/sqlalchemy/engine/base.py", line 3325, in connect
    return self._connection_cls(self, close_with_result=close_with_result)
           ^^^^^^^^^^^^^^^^^^^^^^^^^^^^^^^^^^^^^^^^^^^^^^^^^^^^^^^^^^^^^^^
  File "/home/airflow/.local/lib/python3.11/site-packages/sqlalchemy/engine/base.py", line 96, in __init__
    else engine.raw_connection()
         ^^^^^^^^^^^^^^^^^^^^^^^
  File "/home/airflow/.local/lib/python3.11/site-packages/sqlalchemy/engine/base.py", line 3404, in raw_connection
    return self._wrap_pool_connect(self.pool.connect, _connection)
           ^^^^^^^^^^^^^^^^^^^^^^^^^^^^^^^^^^^^^^^^^^^^^^^^^^^^^^^
  File "/home/airflow/.local/lib/python3.11/site-packages/sqlalchemy/engine/base.py", line 3374, in _wrap_pool_connect
    Connection._handle_dbapi_exception_noconnection(
  File "/home/airflow/.local/lib/python3.11/site-packages/sqlalchemy/engine/base.py", line 2208, in _handle_dbapi_exception_noconnection
    util.raise_(
  File "/home/airflow/.local/lib/python3.11/site-packages/sqlalchemy/util/compat.py", line 211, in raise_
    raise exception
  File "/home/airflow/.local/lib/python3.11/site-packages/sqlalchemy/engine/base.py", line 3371, in _wrap_pool_connect
    return fn()
           ^^^^
  File "/home/airflow/.local/lib/python3.11/site-packages/sqlalchemy/pool/base.py", line 327, in connect
    return _ConnectionFairy._checkout(self)
           ^^^^^^^^^^^^^^^^^^^^^^^^^^^^^^^^
  File "/home/airflow/.local/lib/python3.11/site-packages/sqlalchemy/pool/base.py", line 894, in _checkout
    fairy = _ConnectionRecord.checkout(pool)
            ^^^^^^^^^^^^^^^^^^^^^^^^^^^^^^^^
  File "/home/airflow/.local/lib/python3.11/site-packages/sqlalchemy/pool/base.py", line 493, in checkout
    rec = pool._do_get()
          ^^^^^^^^^^^^^^
  File "/home/airflow/.local/lib/python3.11/site-packages/sqlalchemy/pool/impl.py", line 256, in _do_get
    return self._create_connection()
           ^^^^^^^^^^^^^^^^^^^^^^^^^
  File "/home/airflow/.local/lib/python3.11/site-packages/sqlalchemy/pool/base.py", line 273, in _create_connection
    return _ConnectionRecord(self)
           ^^^^^^^^^^^^^^^^^^^^^^^
  File "/home/airflow/.local/lib/python3.11/site-packages/sqlalchemy/pool/base.py", line 388, in __init__
    self.__connect()
  File "/home/airflow/.local/lib/python3.11/site-packages/sqlalchemy/pool/base.py", line 690, in __connect
    with util.safe_reraise():
  File "/home/airflow/.local/lib/python3.11/site-packages/sqlalchemy/util/langhelpers.py", line 70, in __exit__
    compat.raise_(
  File "/home/airflow/.local/lib/python3.11/site-packages/sqlalchemy/util/compat.py", line 211, in raise_
    raise exception
  File "/home/airflow/.local/lib/python3.11/site-packages/sqlalchemy/pool/base.py", line 686, in __connect
    self.dbapi_connection = connection = pool._invoke_creator(self)
                                         ^^^^^^^^^^^^^^^^^^^^^^^^^^
  File "/home/airflow/.local/lib/python3.11/site-packages/sqlalchemy/engine/create.py", line 574, in connect
    return dialect.connect(*cargs, **cparams)
           ^^^^^^^^^^^^^^^^^^^^^^^^^^^^^^^^^^
  File "/home/airflow/.local/lib/python3.11/site-packages/sqlalchemy/engine/default.py", line 598, in connect
    return self.dbapi.connect(*cargs, **cparams)
           ^^^^^^^^^^^^^^^^^^^^^^^^^^^^^^^^^^^^^
  File "/home/airflow/.local/lib/python3.11/site-packages/psycopg2/__init__.py", line 122, in connect
    conn = _connect(dsn, connection_factory=connection_factory, **kwasync)
           ^^^^^^^^^^^^^^^^^^^^^^^^^^^^^^^^^^^^^^^^^^^^^^^^^^^^^^^^^^^^^^^
sqlalchemy.exc.OperationalError: (psycopg2.OperationalError) could not translate host name "postgres" to address: Temporary failure in name resolution

(Background on this error at: https://sqlalche.me/e/14/e3q8)
[2024-11-12T08:29:00.896+0000] {job.py:226} ERROR - Job heartbeat failed with error. Scheduler is in unhealthy state
[2024-11-12T08:29:06.193+0000] {conn.py:380} INFO - <BrokerConnection node_id=1 host=10.0.2.15:9092 <connecting> [IPv4 ('10.0.2.15', 9092)]>: connecting to 10.0.2.15:9092 [('10.0.2.15', 9092) IPv4]
[2024-11-12T08:29:09.630+0000] {conn.py:410} INFO - <BrokerConnection node_id=1 host=10.0.2.15:9092 <connecting> [IPv4 ('10.0.2.15', 9092)]>: Connection complete.
[2024-11-12T08:29:13.034+0000] {conn.py:919} INFO - <BrokerConnection node_id=bootstrap-0 host=10.0.2.15:9092 <connected> [IPv4 ('10.0.2.15', 9092)]>: Closing connection. 
[2024-11-12T08:29:49.986+0000] {client_async.py:698} WARNING - <BrokerConnection node_id=1 host=10.0.2.15:9092 <connected> [IPv4 ('10.0.2.15', 9092)]> timed out after 30000 ms. Closing connection.
[2024-11-12T08:29:54.822+0000] {conn.py:919} INFO - <BrokerConnection node_id=1 host=10.0.2.15:9092 <connected> [IPv4 ('10.0.2.15', 9092)]>: Closing connection. [Error 7] RequestTimedOutError: Request timed out after 30000 ms
[2024-11-12T08:29:56.163+0000] {client_async.py:331} WARNING - Node 1 connection failed -- refreshing metadata
[2024-11-12T08:29:58.948+0000] {conn.py:380} INFO - <BrokerConnection node_id=1 host=10.0.2.15:9092 <connecting> [IPv4 ('10.0.2.15', 9092)]>: connecting to 10.0.2.15:9092 [('10.0.2.15', 9092) IPv4]
[2024-11-12T08:30:03.573+0000] {conn.py:410} INFO - <BrokerConnection node_id=1 host=10.0.2.15:9092 <connecting> [IPv4 ('10.0.2.15', 9092)]>: Connection complete.
[2024-11-12T08:30:26.815+0000] {job.py:226} ERROR - Job heartbeat failed with error. Scheduler is in unhealthy state
[2024-11-12T08:30:34.379+0000] {client_async.py:698} WARNING - <BrokerConnection node_id=1 host=10.0.2.15:9092 <connected> [IPv4 ('10.0.2.15', 9092)]> timed out after 30000 ms. Closing connection.
[2024-11-12T08:30:38.739+0000] {conn.py:919} INFO - <BrokerConnection node_id=1 host=10.0.2.15:9092 <connected> [IPv4 ('10.0.2.15', 9092)]>: Closing connection. [Error 7] RequestTimedOutError: Request timed out after 30000 ms
[2024-11-12T08:30:42.653+0000] {client_async.py:331} WARNING - Node 1 connection failed -- refreshing metadata
[2024-11-12T08:30:47.597+0000] {conn.py:380} INFO - <BrokerConnection node_id=1 host=10.0.2.15:9092 <connecting> [IPv4 ('10.0.2.15', 9092)]>: connecting to 10.0.2.15:9092 [('10.0.2.15', 9092) IPv4]
[2024-11-12T08:30:51.108+0000] {conn.py:410} INFO - <BrokerConnection node_id=1 host=10.0.2.15:9092 <connecting> [IPv4 ('10.0.2.15', 9092)]>: Connection complete.
